<?xml version="1.0" ?>
<robot name="jaco" xmlns:xacro="http://www.ros.org/wiki/xacro" xmlns:xi="http://www.w3.org/2001/XInclude">
       
  <link name="jaco2_link_base">
    <inertial>
      <origin rpy="0 0 0" xyz="0 0 0"/>
      <mass value="0.1"/>
      <inertia ixx="0.1" ixy="0.0" ixz="0.0" iyy="0.1" iyz="0.0" izz="0.1"/>
    </inertial>
    <visual>
      <geometry>
        <mesh filename="package://kinova_description/meshes/jaco2_link_base.dae"/>
      </geometry>
      <material name="carbon_fiber">
        <color rgba="0.792156862745098 0.819607843137255 0.933333333333333 1"/>
      </material>
    </visual>
    <collision>
      <geometry>
        <mesh filename="package://jaco_description/meshes/base_hull.stl"/>
      </geometry>
    </collision>
  </link>

  <link name="jaco2_link_1">
    <inertial>
      <origin rpy="0 0 0" xyz="0.0692 0.0001 -0.0103"/>
      <mass value="0.748"/>
      <inertia ixx="0.0102" ixy="-5.21e-07" ixz="-0.00212" iyy="0.0325" iyz="-4.14e-07" izz="0.0354"/>
    </inertial>
    <visual>
      <geometry>
        <mesh filename="package://kinova_description/meshes/jaco2_link_1.dae"/>
      </geometry>
      <material name="carbon_fiber">
        <color rgba="0.792156862745098 0.819607843137255 0.933333333333333 1"/>
      </material>
    </visual>
    <collision>
      <origin rpy="0 0 0" xyz="0 0 0" />
      <geometry>
	<mesh filename="package://jaco_description/meshes/link1_hull.stl" />
      </geometry>
    </collision>
  </link>

  <joint name="jaco2_joint_1" type="revolute">
    <parent link="jaco2_link_base"/>
    <child link="jaco2_link_1"/>
    <axis xyz="0 0 -1"/>
    <!-- <limit effort="30" lower="-3.14159" upper="3.14159" velocity="0.5"/> -->
    <limit effort="30" lower="-4.712385" upper="1.570795" velocity="0.5"/> <!-- Actual saturation: 0.65 -->
    <origin rpy="3.14159265359 0 3.14159265359" xyz="0 0 0.1535"/>
  </joint>

  <link name="jaco2_link_2">
    <inertial>
      <origin rpy="0 0 0" xyz="0.2052 0.0000 0.0223"/>
      <mass value="1.011"/>
      <inertia ixx="0.379" ixy="0.0" ixz="0.0" iyy="0.373" iyz="-5.9e-06" izz="0.00698"/>
    </inertial>
    <visual>
      <geometry>
        <mesh filename="package://kinova_description/meshes/jaco2_link_2.dae"/>
      </geometry>
      <material name="carbon_fiber">
        <color rgba="0.792156862745098 0.819607843137255 0.933333333333333 1"/>
      </material>
    </visual>
    <collision>
      <geometry>
        <mesh filename="package://jaco_description/meshes/link2_hull.stl"/>
      </geometry>
    </collision>
  </link>

  <joint name="jaco2_joint_2" type="revolute">
    <parent link="jaco2_link_1"/>
    <child link="jaco2_link_2"/>
    <axis xyz="0 0 1"/>
    <limit effort="30" lower="-3.9" upper="0.0" velocity="0.9"/>
    <origin rpy="-1.57079632679 3.14159265359 0" xyz="0 0 -0.1185"/>
  </joint>

  <link name="jaco2_link_3">
    <inertial>
      <origin rpy="0 0 0" xyz="0.0196 0.0000 0.0644"/>
      <mass value="0.568"/>
      <inertia ixx="0.0511" ixy="1.92e-07" ixz="-2.67e-07" iyy="0.144" iyz="-9.59e-05" izz="0.0129"/>
    </inertial>
    <visual>
      <geometry>
        <mesh filename="package://kinova_description/meshes/jaco2_link_3.dae"/>
      </geometry>
      <material name="carbon_fiber">
        <color rgba="0.792156862745098 0.819607843137255 0.933333333333333 1"/>
      </material>
    </visual>
    <collision>
      <geometry>
        <mesh filename="package://jaco_description/meshes/link3_hull.stl"/>
      </geometry>
    </collision>
  </link>

  <joint name="jaco2_joint_3" type="revolute">
    <parent link="jaco2_link_2"/>
    <child link="jaco2_link_3"/>
    <axis xyz="0 0 -1"/>
    <limit effort="30" lower="-3.92699081699" upper="0.785398163397" velocity="0.5"/> <!-- Actual saturation: 0.65 -->
    <origin rpy="3.14159265359 0 1.57079632679" xyz="0.41 0 0"/>
  </joint>

  <link name="jaco2_link_4">
    <inertial>
      <origin rpy="0 0 0" xyz="0.0086 0.0000 -0.0374"/>
      <mass value="0.427"/>
      <inertia ixx="0.00246" ixy="0.000833" ixz="3.35e-08" iyy="0.00342" iyz="3.4e-08" izz="0.00363"/>
    </inertial>
    <visual>
      <geometry>
        <mesh filename="package://kinova_description/meshes/jaco2_link_4.dae"/>
      </geometry>
      <material name="carbon_fiber">
        <color rgba="0.792156862745098 0.819607843137255 0.933333333333333 1"/>
      </material>
    </visual>
    <collision>
      <geometry>
        <mesh filename="package://jaco_description/meshes/link4_hull.stl"/>
      </geometry>
    </collision>
  </link>

  <joint name="jaco2_joint_4" type="revolute">
    <parent link="jaco2_link_3"/>
    <child link="jaco2_link_4"/>
    <axis xyz="0 0 -1"/>
    <limit effort="30" lower="-3.14159" upper="3.14159" velocity="0.9"/>
    <origin rpy="3.14159265359 1.57079632679 0" xyz="0.207 0 -0.01125"/>
  </joint>

  <link name="jaco2_link_5">
    <inertial>
      <origin rpy="0 0 0" xyz="0.0086 0.0000 -0.0374"/>
      <mass value="0.427"/>
      <inertia ixx="0.00246" ixy="0.000833" ixz="3.35e-08" iyy="0.00342" iyz="3.4e-08" izz="0.00363"/>
    </inertial>
    <visual>
      <geometry>
        <mesh filename="package://kinova_description/meshes/jaco2_link_5.dae"/>
      </geometry>
      <material name="carbon_fiber">
        <color rgba="0.792156862745098 0.819607843137255 0.933333333333333 1"/>
      </material>
    </visual>
    <collision>
      <geometry>
        <mesh filename="package://jaco_description/meshes/link5_hull.stl"/>
      </geometry>
    </collision>
  </link>

  <joint name="jaco2_joint_5" type="revolute">
    <parent link="jaco2_link_4"/>
    <child link="jaco2_link_5"/>
    <axis xyz="0 0 -1"/>
    <limit effort="30" lower="-3.14159" upper="3.14159" velocity="0.9"/>
    <origin rpy="0 -1.0471975512 0" xyz="0.03700 0 -0.06408"/>
  </joint>

  <link name="jaco2_wrist">
    <visual>
      <geometry>
	<sphere radius="0.01"/>
      </geometry>
    </visual>
  </link>

  <!-- <joint name="jaco2_joint_6" type="continuous"> -->
  <joint name="jaco2_joint_6" type="revolute">
    <parent link="jaco2_link_5"/>
    <child link="jaco2_wrist"/>
    <axis xyz="0 0 -1"/>
    <limit effort="30" lower="-3.14159265359" upper="6.28" velocity="0.75"/> <!-- actual saturation: 0.85 -->
    <origin rpy="-1.0471975512 0 1.57079632679" xyz="0.03700 0 -0.06408"/>
  </joint>

  <joint name="jaco2_wrist_to_link_hand" type="fixed">
    <parent link="jaco2_wrist"/>
    <child link="jaco2_link_hand"/>
    <origin rpy="0 0 0" xyz="0 0 0"/>
  </joint>

  <link name="jaco2_link_hand">
    <inertial>
      <origin rpy="0 0 0" xyz="0.0068 0.0000 -0.0822"/>
      <mass value="0.727"/>
      <inertia ixx="0.00466" ixy="0.000413" ixz="-1.05e-05" iyy="0.00265" iyz="-3.24e-06" izz="0.00525"/>
    </inertial>
    <visual>
      <origin xyz="0 0 0" rpy="-1.5708 0 0" />
      <geometry>
        <!-- <mesh filename="package://kinova_description/meshes/jaco2_link_hand.dae"/> -->
	<mesh filename="package://jaco_description/meshes/hand.STL" />
      </geometry>
      <material name="carbon_fiber">
        <color rgba="0.792156862745098 0.819607843137255 0.933333333333333 1"/>
      </material>
    </visual>
    <collision>
      <geometry>
        <mesh filename="package://jaco_description/meshes/hand_hull.stl"/>
      </geometry>
    </collision>
  </link>

  <joint name="jaco2_link_hand_to_end_effector" type="fixed">
    <parent link="jaco2_link_hand"/>
    <child link="jaco2_end_effector"/>
    <origin rpy="0 3.14159265359 0" xyz="0 0 -0.1687"/>
  </joint>

  <link name="jaco2_end_effector">
  </link>

  <link name="jaco2_link_finger_1">
    <!-- Inertia included in the hand link -->
    <inertial>
      <origin rpy="0 0 0" xyz="0 0 0"/>
      <mass value="0.010"/>
      <inertia ixx="0.010" ixy="0" ixz="0" iyy="0.010" iyz="0" izz="0.010"/>
    </inertial>
    <visual>
      <geometry>
        <!--mesh filename="package://kinova_description/meshes/jaco2_link_finger_1.dae"/-->
	<mesh filename="package://jaco_description/meshes/finger.stl"/>
      </geometry>
      <material name="carbon_fiber">
        <color rgba="0.792156862745098 0.819607843137255 0.933333333333333 1"/>
      </material>
    </visual>
    <collision>
      <geometry>
        <!--mesh filename="package://kinova_description/meshes/jaco2_link_finger_1.dae"/-->
	<mesh filename="package://jaco_description/meshes/finger.stl"/>
      </geometry>
    </collision>
  </link>

  <joint name="jaco2_joint_finger_1" type="revolute">
    <parent link="jaco2_link_hand"/>
    <child link="jaco2_link_finger_1"/>
    <axis xyz="0 0 1"/>
    <origin rpy="-1.7983 1.117 3.1416" xyz="-0.03141 0.00279 -0.11433"/>
    <limit effort="30" lower="0" upper="0.77" velocity="5"/>
  </joint>

  <link name="jaco2_link_finger_1_tip">
    <visual>
      <geometry>
	<mesh filename="package://jaco_description/meshes/finger_tip.stl"/>
      </geometry>
      <material name="carbon_fiber">
        <color rgba="0.792156862745098 0.819607843137255 0.933333333333333 1"/>
      </material>
    </visual>
    <collision>
      <geometry>
	<mesh filename="package://jaco_description/meshes/finger_tip.stl"/>
      </geometry>
    </collision>
  </link>
  
  <joint name="jaco2_joint_finger_1_tip" type="revolute">
    <axis xyz="0 0 1" />
    <parent link="jaco2_link_finger_1" />
    <child link="jaco2_link_finger_1_tip" />
    <origin xyz="0.044 -0.003 0" rpy="0 0 -0.2" />
    <limit effort="30" lower="0" upper=".5775" velocity="5" />
    <mimic joint="jaco2_joint_finger_1" multiplier="0.75" />
  </joint>

  <link name="jaco2_link_finger_2">
    <!-- Inertia included in the hand link -->
    <inertial>
      <origin rpy="0 0 0" xyz="0 0 0"/>
      <mass value="0.010"/>
      <inertia ixx="0.010" ixy="0" ixz="0" iyy="0.010" iyz="0" izz="0.010"/>
    </inertial>
    <visual>
      <geometry>
        <!--mesh filename="package://kinova_description/meshes/jaco2_link_finger_2.dae"/-->
	<mesh filename="package://jaco_description/meshes/finger.stl"/>
      </geometry>
      <material name="carbon_fiber">
        <color rgba="0.792156862745098 0.819607843137255 0.933333333333333 1"/>
      </material>
    </visual>
    <collision>
      <geometry>
        <!--mesh filename="package://kinova_description/meshes/jaco2_link_finger_2.dae"/-->
	<mesh filename="package://jaco_description/meshes/finger.stl"/>
      </geometry>
    </collision>
  </link>

  <joint name="jaco2_joint_finger_2" type="revolute">
    <parent link="jaco2_link_hand"/>
    <child link="jaco2_link_finger_2"/>
    <axis xyz="0 0 1"/>
    <origin rpy="-1.6222 1.117 -0.23615" xyz="0.02707 -0.02226 -0.11457"/>
    <limit effort="30" lower="0" upper="0.77" velocity="5"/>
  </joint>

  <link name="jaco2_link_finger_2_tip">
    <visual>
      <geometry>
	<mesh filename="package://jaco_description/meshes/finger_tip.stl"/>
      </geometry>
      <material name="carbon_fiber">
	<color rgba="0.792156862745098 0.819607843137255 0.933333333333333 1"/>
      </material>
    </visual>
    <collision>
      <geometry>
	<mesh filename="package://jaco_description/meshes/finger_tip.stl"/>
      </geometry>
    </collision>
  </link>

  <joint name="jaco2_joint_finger_2_tip" type="revolute">
    <axis xyz="0 0 1" />
    <parent link="jaco2_link_finger_2" />
    <child link="jaco2_link_finger_2_tip" />
    <origin xyz="0.044 -0.003 0" rpy="0 0 -0.2" />
    <limit effort="30" lower="0" upper=".5775" velocity="5" />
    <mimic joint="jaco2_joint_finger_2" multiplier="0.75" />
  </joint>

  <link name="jaco2_link_finger_3">
    <!-- Inertia included in the hand link -->
    <inertial>
      <origin rpy="0 0 0" xyz="0 0 0"/>
      <mass value="0.010"/>
      <inertia ixx="0.010" ixy="0" ixz="0" iyy="0.010" iyz="0" izz="0.010"/>
    </inertial>
    <visual>
      <geometry>
        <!--mesh filename="package://kinova_description/meshes/jaco2_link_finger_3.dae"/-->
	<mesh filename="package://jaco_description/meshes/finger.stl"/>
      </geometry>
      <material name="carbon_fiber">
        <color rgba="0.792156862745098 0.819607843137255 0.933333333333333 1"/>
      </material>
    </visual>
    <collision>
      <geometry>
        <!--mesh filename="package://kinova_description/meshes/jaco2_link_finger_3.dae"/-->
	<mesh filename="package://jaco_description/meshes/finger.stl"/>
      </geometry>
    </collision>
  </link>

  <joint name="jaco2_joint_finger_3" type="revolute">
    <parent link="jaco2_link_hand"/>
    <child link="jaco2_link_finger_3"/>
    <axis xyz="0 0 1"/>
    <!--origin rpy="-1.5161 1.1459 0.23978" xyz="0.03569 0.0216 -0.10071"/-->
    <origin xyz="0.03141 0.02226 -0.11457" rpy="-1.5161 1.1459 0.23978"/>
    <limit effort="30" lower="0" upper="0.77" velocity="5"/>
  </joint>

  <link name="jaco2_link_finger_3_tip">
    <visual>
      <geometry>
	<mesh filename="package://jaco_description/meshes/finger_tip.stl"/>
      </geometry>
      <material name="carbon_fiber">
        <color rgba="0.792156862745098 0.819607843137255 0.933333333333333 1"/>
      </material>
    </visual>
    <collision>
      <geometry>
	<mesh filename="package://jaco_description/meshes/finger_tip.stl"/>
      </geometry>
    </collision>
  </link>

  <joint name="jaco2_joint_finger_3_tip" type="revolute">
    <axis xyz="0 0 1" />
    <parent link="jaco2_link_finger_3" />
    <child link="jaco2_link_finger_3_tip" />
    <origin xyz="0.044 -0.003 0" rpy="0 0 -0.2" />
    <limit effort="30" lower="0" upper=".5775" velocity="5" />
    <mimic joint="jaco2_joint_finger_3" multiplier="0.75" />
  </joint>

</robot>

