<?xml version="1.0" ?>
<!-- =================================================================================== -->
<!-- |    This document was autogenerated by xacro from standalone_jaco2.xacro         | -->
<!-- |    EDITING THIS FILE BY HAND IS NOT RECOMMENDED                                 | -->
<!-- =================================================================================== -->
<robot name="jaco" xmlns:body="http://playerstage.sourceforge.net/gazebo/xmlschema/#body" xmlns:controller="http://playerstage.sourceforge.net/gazebo/xmlschema/#controller" xmlns:gazebo="http://playerstage.sourceforge.net/gazebo/xmlschema/#gz" xmlns:geom="http://playerstage.sourceforge.net/gazebo/xmlschema/#geom" xmlns:interface="http://playerstage.sourceforge.net/gazebo/xmlschema/#interface" xmlns:joint="http://playerstage.sourceforge.net/gazebo/xmlschema/#joint" xmlns:model="http://playerstage.sourceforge.net/gazebo/xmlschema/#model" xmlns:physics="http://playerstage.sourceforge.net/gazebo/xmlschema/#physics" xmlns:renderable="http://playerstage.sourceforge.net/gazebo/xmlschema/#renderable" xmlns:rendering="http://playerstage.sourceforge.net/gazebo/xmlschema/#rendering" xmlns:sensor="http://playerstage.sourceforge.net/gazebo/xmlschema/#sensor" xmlns:xacro="http://ros.org/wiki/xacro" xmlns:xi="http://www.w3.org/2001/XInclude">
  <link name="root">
    <visual>
      <origin rpy="0 0 0" xyz="0 0 0"/>
      <geometry>
        <box size="0 0 0"/>
        <!--making it slightly bigger in x and z direction-->
      </geometry>
      <!--<material name="Black" /> -->
    </visual>
    <collision>
      <origin rpy="0 0 0" xyz="0 0 0"/>
      <geometry>
        <box size="0 0 0"/>
        <!--making it slightly bigger in x and z direction-->
      </geometry>
    </collision>
  </link>
  <link name="jaco2_link_base">
    <inertial>
      <origin rpy="0 0 0" xyz="0 0 0"/>
      <mass value="0.1"/>
      <inertia ixx="0.1" ixy="0.0" ixz="0.0" iyy="0.1" iyz="0.0" izz="0.1"/>
    </inertial>
    <visual>
      <geometry>
        <mesh filename="package://kinova_description/meshes/jaco2_link_base.dae"/>
      </geometry>
      <material name="carbon_fiber">
        <color rgba="0.792156862745098 0.819607843137255 0.933333333333333 1"/>
      </material>
    </visual>
    <collision>
      <geometry>
        <mesh filename="package://kinova_description/meshes/jaco2_link_base.dae"/>
      </geometry>
    </collision>
  </link>
  <joint name="jaco2_joint_base" type="fixed">
    <parent link="root"/>
    <child link="jaco2_link_base"/>
    <axis xyz="0 0 0"/>
    <origin rpy="0 0 0" xyz="0 0 0"/>
  </joint>
  <link name="jaco2_link_1">
    <inertial>
      <origin rpy="0 0 0" xyz="0.0692 0.0001 -0.0103"/>
      <mass value="0.748"/>
      <inertia ixx="0.0102" ixy="-5.21e-07" ixz="-0.00212" iyy="0.0325" iyz="-4.14e-07" izz="0.0354"/>
    </inertial>
    <visual>
      <geometry>
        <mesh filename="package://kinova_description/meshes/jaco2_link_1.dae"/>
      </geometry>
      <material name="carbon_fiber">
        <color rgba="0.792156862745098 0.819607843137255 0.933333333333333 1"/>
      </material>
    </visual>
    <collision>
      <geometry>
        <mesh filename="package://kinova_description/meshes/jaco2_link_1.dae"/>
      </geometry>
    </collision>
  </link>
  <joint name="jaco2_joint_1" type="continuous">
    <parent link="jaco2_link_base"/>
    <child link="jaco2_link_1"/>
    <axis xyz="0 0 -1"/>
    <limit effort="30" lower="-6.28318530718" upper="6.28318530718" velocity="0.35"/>
    <origin rpy="3.14159265359 0 3.14159265359" xyz="0 0 0.1535"/>
  </joint>
  <transmission name="jaco2_joint_1_trans">
    <type>transmission_interface/SimpleTransmission</type>
    <joint name="jaco2_joint_1">
      <hardwareInterface>EffortJointInterface</hardwareInterface>
    </joint>
    <actuator name="jaco2_joint_1_motor">
      <mechanicalReduction>1.0</mechanicalReduction>
    </actuator>
  </transmission>
  <link name="jaco2_link_2">
    <inertial>
      <origin rpy="0 0 0" xyz="0.2052 0.0000 0.0223"/>
      <mass value="1.011"/>
      <inertia ixx="0.379" ixy="0.0" ixz="0.0" iyy="0.373" iyz="-5.9e-06" izz="0.00698"/>
    </inertial>
    <visual>
      <geometry>
        <mesh filename="package://kinova_description/meshes/jaco2_link_2.dae"/>
      </geometry>
      <material name="carbon_fiber">
        <color rgba="0.792156862745098 0.819607843137255 0.933333333333333 1"/>
      </material>
    </visual>
    <collision>
      <geometry>
        <mesh filename="package://kinova_description/meshes/jaco2_link_2.dae"/>
      </geometry>
    </collision>
  </link>
  <joint name="jaco2_joint_2" type="revolute">
    <parent link="jaco2_link_1"/>
    <child link="jaco2_link_2"/>
    <axis xyz="0 0 1"/>
    <limit effort="30" lower="-3.14159265359" upper="0.0" velocity="0.35"/>
    <origin rpy="-1.57079632679 3.14159265359 0" xyz="0 0 -0.1185"/>
  </joint>
  <transmission name="jaco2_joint_2_trans">
    <type>transmission_interface/SimpleTransmission</type>
    <joint name="jaco2_joint_2">
      <hardwareInterface>EffortJointInterface</hardwareInterface>
    </joint>
    <actuator name="jaco2_joint_2_motor">
      <mechanicalReduction>1.0</mechanicalReduction>
    </actuator>
  </transmission>
  <link name="jaco2_link_3">
    <inertial>
      <origin rpy="0 0 0" xyz="0.0196 0.0000 0.0644"/>
      <mass value="0.568"/>
      <inertia ixx="0.0511" ixy="1.92e-07" ixz="-2.67e-07" iyy="0.144" iyz="-9.59e-05" izz="0.0129"/>
    </inertial>
    <visual>
      <geometry>
        <mesh filename="package://kinova_description/meshes/jaco2_link_3.dae"/>
      </geometry>
      <material name="carbon_fiber">
        <color rgba="0.792156862745098 0.819607843137255 0.933333333333333 1"/>
      </material>
    </visual>
    <collision>
      <geometry>
        <mesh filename="package://kinova_description/meshes/jaco2_link_3.dae"/>
      </geometry>
    </collision>
  </link>
  <joint name="jaco2_joint_3" type="revolute">
    <parent link="jaco2_link_2"/>
    <child link="jaco2_link_3"/>
    <axis xyz="0 0 -1"/>
    <limit effort="30" lower="-3.92699081699" upper="0.785398163397" velocity="0.35"/>
    <origin rpy="3.14159265359 0 1.57079632679" xyz="0.41 0 0"/>
  </joint>
  <transmission name="jaco2_joint_3_trans">
    <type>transmission_interface/SimpleTransmission</type>
    <joint name="jaco2_joint_3">
      <hardwareInterface>EffortJointInterface</hardwareInterface>
    </joint>
    <actuator name="jaco2_joint_3_motor">
      <mechanicalReduction>1.0</mechanicalReduction>
    </actuator>
  </transmission>
  <link name="jaco2_link_4">
    <inertial>
      <origin rpy="0 0 0" xyz="0.0086 0.0000 -0.0374"/>
      <mass value="0.427"/>
      <inertia ixx="0.00246" ixy="0.000833" ixz="3.35e-08" iyy="0.00342" iyz="3.4e-08" izz="0.00363"/>
    </inertial>
    <visual>
      <geometry>
        <mesh filename="package://kinova_description/meshes/jaco2_link_4.dae"/>
      </geometry>
      <material name="carbon_fiber">
        <color rgba="0.792156862745098 0.819607843137255 0.933333333333333 1"/>
      </material>
    </visual>
    <collision>
      <geometry>
        <mesh filename="package://kinova_description/meshes/jaco2_link_4.dae"/>
      </geometry>
    </collision>
  </link>
  <joint name="jaco2_joint_4" type="continuous">
    <parent link="jaco2_link_3"/>
    <child link="jaco2_link_4"/>
    <axis xyz="0 0 -1"/>
    <limit effort="30" lower="-6.28318530718" upper="6.28318530718" velocity="0.35"/>
    <origin rpy="3.14159265359 1.57079632679 0" xyz="0.207 0 -0.01125"/>
  </joint>
  <transmission name="jaco2_joint_4_trans">
    <type>transmission_interface/SimpleTransmission</type>
    <joint name="jaco2_joint_4">
      <hardwareInterface>EffortJointInterface</hardwareInterface>
    </joint>
    <actuator name="jaco2_joint_4_motor">
      <mechanicalReduction>1.0</mechanicalReduction>
    </actuator>
  </transmission>
  <link name="jaco2_link_5">
    <inertial>
      <origin rpy="0 0 0" xyz="0.0086 0.0000 -0.0374"/>
      <mass value="0.427"/>
      <inertia ixx="0.00246" ixy="0.000833" ixz="3.35e-08" iyy="0.00342" iyz="3.4e-08" izz="0.00363"/>
    </inertial>
    <visual>
      <geometry>
        <mesh filename="package://kinova_description/meshes/jaco2_link_5.dae"/>
      </geometry>
      <material name="carbon_fiber">
        <color rgba="0.792156862745098 0.819607843137255 0.933333333333333 1"/>
      </material>
    </visual>
    <collision>
      <geometry>
        <mesh filename="package://kinova_description/meshes/jaco2_link_5.dae"/>
      </geometry>
    </collision>
  </link>
  <joint name="jaco2_joint_5" type="continuous">
    <parent link="jaco2_link_4"/>
    <child link="jaco2_link_5"/>
    <axis xyz="0 0 -1"/>
    <limit effort="30" lower="-6.28318530718" upper="6.28318530718" velocity="0.35"/>
    <origin rpy="0 -1.0471975512 0" xyz="0.03700 0 -0.06408"/>
  </joint>
  <transmission name="jaco2_joint_5_trans">
    <type>transmission_interface/SimpleTransmission</type>
    <joint name="jaco2_joint_5">
      <hardwareInterface>EffortJointInterface</hardwareInterface>
    </joint>
    <actuator name="jaco2_joint_5_motor">
      <mechanicalReduction>1.0</mechanicalReduction>
    </actuator>
  </transmission>
  <link name="jaco2_link_hand">
    <inertial>
      <origin rpy="0 0 0" xyz="0.0068 0.0000 -0.0822"/>
      <mass value="0.727"/>
      <inertia ixx="0.00466" ixy="0.000413" ixz="-1.05e-05" iyy="0.00265" iyz="-3.24e-06" izz="0.00525"/>
    </inertial>
    <visual>
      <geometry>
        <mesh filename="package://kinova_description/meshes/jaco2_link_hand.dae"/>
      </geometry>
      <material name="carbon_fiber">
        <color rgba="0.792156862745098 0.819607843137255 0.933333333333333 1"/>
      </material>
    </visual>
    <collision>
      <geometry>
        <mesh filename="package://kinova_description/meshes/jaco2_link_hand.dae"/>
      </geometry>
    </collision>
  </link>
  <joint name="jaco2_joint_6" type="continuous">
    <parent link="jaco2_link_5"/>
    <child link="jaco2_link_hand"/>
    <axis xyz="0 0 -1"/>
    <limit effort="30" lower="-6.28318530718" upper="6.28318530718" velocity="0.35"/>
    <origin rpy="-1.0471975512 0 1.57079632679" xyz="0.03700 0 -0.06408"/>
  </joint>
  <transmission name="jaco2_joint_6_trans">
    <type>transmission_interface/SimpleTransmission</type>
    <joint name="jaco2_joint_6">
      <hardwareInterface>EffortJointInterface</hardwareInterface>
    </joint>
    <actuator name="jaco2_joint_6_motor">
      <mechanicalReduction>1.0</mechanicalReduction>
    </actuator>
  </transmission>
  <joint name="jaco2_link_base_to_api_origin" type="fixed">
    <parent link="jaco2_link_base"/>
    <child link="jaco2_api_origin"/>
    <origin rpy="0 0 0" xyz="0 0 0.028"/>
  </joint>
  <link name="jaco2_api_origin">
    <!--
         <visual>
           <geometry>
             <box xyz="0 0 0" size="0.1 0.1 0.1"/>
           </geometry>
         </visual>
         <collision>
           <geometry>
             <box xyz="0 0 0" size="0.1 0.1 0.1"/>
           </geometry>
         </collision>
         -->
  </link>
  <joint name="jaco2_link_hand_to_end_effector" type="fixed">
    <parent link="jaco2_link_hand"/>
    <child link="jaco2_end_effector"/>
    <origin rpy="0 3.14159265359 0" xyz="0 0 -0.1687"/>
  </joint>
  <link name="jaco2_end_effector"/>
  <gazebo reference="jaco2_link_base">
    <material>Gazebo/Black</material>
    <selfCollide>false</selfCollide>
    <gravity>false</gravity>
  </gazebo>
  <gazebo>
    <plugin filename="libgazebo_ros_control.so" name="gazebo_ros_control"/>
  </gazebo>
  <link name="jaco2_link_finger_1">
    <!-- Inertia included in the hand link -->
    <inertial>
      <origin rpy="0 0 0" xyz="0 0 0"/>
      <mass value="0.010"/>
      <inertia ixx="0.010" ixy="0" ixz="0" iyy="0.010" iyz="0" izz="0.010"/>
    </inertial>
    <visual>
      <geometry>
        <mesh filename="package://kinova_description/meshes/jaco2_link_finger_1.dae"/>
      </geometry>
      <material name="carbon_fiber">
        <color rgba="0.792156862745098 0.819607843137255 0.933333333333333 1"/>
      </material>
    </visual>
    <collision>
      <geometry>
        <mesh filename="package://kinova_description/meshes/jaco2_link_finger_1.dae"/>
      </geometry>
    </collision>
  </link>
  <joint name="jaco2_joint_finger_1" type="revolute">
    <parent link="jaco2_link_hand"/>
    <child link="jaco2_link_finger_1"/>
    <axis xyz="0 0 1"/>
    <origin rpy="-1.7983 1.117 3.1416" xyz="-0.03978 0 -0.10071"/>
    <limit effort="30" lower="0" upper="0.698131700798" velocity="5"/>
  </joint>
  <transmission name="jaco2_joint_finger_1_trans">
    <type>transmission_interface/SimpleTransmission</type>
    <joint name="jaco2_joint_finger_1">
      <hardwareInterface>EffortJointInterface</hardwareInterface>
    </joint>
    <actuator name="jaco2_joint_finger_1_motor">
      <mechanicalReduction>1.0</mechanicalReduction>
    </actuator>
  </transmission>
  <link name="jaco2_link_finger_2">
    <!-- Inertia included in the hand link -->
    <inertial>
      <origin rpy="0 0 0" xyz="0 0 0"/>
      <mass value="0.010"/>
      <inertia ixx="0.010" ixy="0" ixz="0" iyy="0.010" iyz="0" izz="0.010"/>
    </inertial>
    <visual>
      <geometry>
        <mesh filename="package://kinova_description/meshes/jaco2_link_finger_2.dae"/>
      </geometry>
      <material name="carbon_fiber">
        <color rgba="0.792156862745098 0.819607843137255 0.933333333333333 1"/>
      </material>
    </visual>
    <collision>
      <geometry>
        <mesh filename="package://kinova_description/meshes/jaco2_link_finger_2.dae"/>
      </geometry>
    </collision>
  </link>
  <joint name="jaco2_joint_finger_2" type="revolute">
    <parent link="jaco2_link_hand"/>
    <child link="jaco2_link_finger_2"/>
    <axis xyz="0 0 1"/>
    <origin rpy="-1.6222 1.117 -0.23615" xyz="0.03569 -0.0216 -0.10071"/>
    <limit effort="30" lower="0" upper="0.698131700798" velocity="5"/>
  </joint>
  <transmission name="jaco2_joint_finger_2_trans">
    <type>transmission_interface/SimpleTransmission</type>
    <joint name="jaco2_joint_finger_2">
      <hardwareInterface>EffortJointInterface</hardwareInterface>
    </joint>
    <actuator name="jaco2_joint_finger_2_motor">
      <mechanicalReduction>1.0</mechanicalReduction>
    </actuator>
  </transmission>
  <link name="jaco2_link_finger_3">
    <!-- Inertia included in the hand link -->
    <inertial>
      <origin rpy="0 0 0" xyz="0 0 0"/>
      <mass value="0.010"/>
      <inertia ixx="0.010" ixy="0" ixz="0" iyy="0.010" iyz="0" izz="0.010"/>
    </inertial>
    <visual>
      <geometry>
        <mesh filename="package://kinova_description/meshes/jaco2_link_finger_3.dae"/>
      </geometry>
      <material name="carbon_fiber">
        <color rgba="0.792156862745098 0.819607843137255 0.933333333333333 1"/>
      </material>
    </visual>
    <collision>
      <geometry>
        <mesh filename="package://kinova_description/meshes/jaco2_link_finger_3.dae"/>
      </geometry>
    </collision>
  </link>
  <joint name="jaco2_joint_finger_3" type="revolute">
    <parent link="jaco2_link_hand"/>
    <child link="jaco2_link_finger_3"/>
    <axis xyz="0 0 1"/>
    <origin rpy="-1.5161 1.1459 0.23978" xyz="0.03569 0.0216 -0.10071"/>
    <limit effort="30" lower="0" upper="0.698131700798" velocity="5"/>
  </joint>
  <transmission name="jaco2_joint_finger_3_trans">
    <type>transmission_interface/SimpleTransmission</type>
    <joint name="jaco2_joint_finger_3">
      <hardwareInterface>EffortJointInterface</hardwareInterface>
    </joint>
    <actuator name="jaco2_joint_finger_3_motor">
      <mechanicalReduction>1.0</mechanicalReduction>
    </actuator>
  </transmission>
  <!-- Used to fix the model to the ground in Gazebo. -->
  <link name="world"/>
  <joint name="world_2_root_fixed" type="fixed">
    <parent link="world"/>
    <child link="root"/>
  </joint>
</robot>

